Workbook

Sheet Sintesi
B3: L’analisi ha l’obiettivo di creare una vista aggregata dell’impatto derivante dalle diverse scelte di soglia sugli scenari 14, 90, 30, 100, 95 e DF03-02 ai fini di reporting. Per utilizzare lo strumento è sufficiente selezionare le soglie all’interno dei file Excel degli scenari. L’aggregatore attuale recupera automaticamente i dati necessari dai file degli scenari e calcola l’impatto complessivo. Per confrontare le opzioni prudenziale, intermedia e aggressiva è sufficiente raccogliere manualmente i risultati prodotti dallo strumento ed effettuare il confronto.
F17: Scelta BPPB | P17: Interval analisis
F18: Prudenziale | H18: Intermedio | J18: Aggressivo | P18: Prudenziale | R18: Intermedio | T18: Aggressivo
A19: Totale alert top 6 calibrata | B19: =B23+B21 -> 1932 | C19: =B19=T19 -> TRUE | E19: Totale alert top 6 calibrata | F19: 2695 | H19: 2393 | J19: 2045 | O19: Totale alert top 6 calibrata | P19: 2894 | R19: 2480 | T19: 1932
A20: Totale alert top 6 as is | B20: =Analisi!B38 -> 3027 | C20: =B20=T20 -> TRUE | E20: Totale alert top 6 as is | F20: 3027 | G20: =(F20-F19)/F20 -> 0.10967955 | H20: 3027 | I20: =(H20-H19)/H20 -> 0.2094483 | J20: 3027 | K20: =(J20-J19)/J20 -> 0.32441361 | O20: Totale alert top 6 as is | P20: 3027 | Q20: =(P20-P19)/P20 -> 0.043937892 | R20: 3027 | S20: =(R20-R19)/R20 -> 0.18070697 | T20: 3027 | U20: =(T20-T19)/T20 -> 0.3617443
A21: FP Calibrata | B21: =Analisi!B42 -> 861 | C21: =B21=T21 -> TRUE | E21: FP Calibrata | F21: 1236 | H21: 1083 | J21: 888 | O21: FP Calibrata | P21: 1356 | R21: 1138 | T21: 861
A22: FP as-is | B22: =Analisi!B50 -> 1421 | C22: =B22=T22 -> TRUE | E22: FP as-is | F22: 1421 | G22: =(F22-F21)/F22 -> 0.13019001 | H22: 1421 | I22: =(H22-H21)/H22 -> 0.23786066 | J22: 1421 | K22: =(J22-J21)/J22 -> 0.37508797 | O22: FP as-is | P22: 1421 | Q22: =(P22-P21)/P22 -> 0.045742435 | R22: 1421 | S22: =(R22-R21)/R22 -> 0.19915552 | T22: 1421 | U22: =(T22-T21)/T22 -> 0.39408867
A23: Open Alert Calibrata | B23: =Analisi!B43 -> 1071 | C23: =B23=T23 -> TRUE | E23: Open Alert Calibrata | F23: 1459 | H23: 1310 | J23: 1157 | O23: Open Alert Calibrata | P23: 1538 | R23: 1342 | T23: 1071
A24: Open Alert as-is | B24: =Analisi!B51 -> 1606 | C24: =B24=T24 -> TRUE | E24: Open Alert as-is | F24: 1606 | G24: =(F24-F23)/F24 -> 0.091531756 | H24: 1606 | I24: =(H24-H23)/H24 -> 0.18430884 | J24: 1606 | K24: =(J24-J23)/J24 -> 0.27957659 | O24: Open Alert as-is | P24: 1606 | Q24: =(P24-P23)/P24 -> 0.04234122 | R24: 1606 | S24: =(R24-R23)/R24 -> 0.16438356 | T24: 1606 | U24: =(T24-T23)/T24 -> 0.33312578
A25: Spostamento delle soglie | B25: =Analisi!G60 -> 1.5210662 | C25: =B25=T25 -> TRUE | E25: Spostamento delle soglie | F25: 0.13632945 | H25: 0.41133483 | J25: 0.73084056 | O25: Spostamento delle soglie | P25: 0.1402699 | R25: 0.47681378 | T25: 1.5210662
F27: Controlli di correttezza | P27: Controlli di correttezza
F29: =F19=(F23+F21) -> TRUE | H29: =H19=(H23+H21) -> TRUE | J29: =J19=(J23+J21) -> TRUE | P29: =P19=(P21+P23) -> TRUE | R29: =R19=(R21+R23) -> TRUE | T29: =T19=(T21+T23) -> TRUE
F30: =F20=(F24+F22) -> TRUE | H30: =H20=(H24+H22) -> TRUE | J30: =J20=(J24+J22) -> TRUE | P30: =P20=(P22+P24) -> TRUE | R30: =R20=(R22+R24) -> TRUE | T30: =T20=(T22+T24) -> TRUE
F37: Prudenziale | G37: Intermedio | H37: Aggressivo | P37: Soglia di percentile 5 | Q37: Soglia di percentile 25 | R37: Soglia di percentile 50
E38: Spostamento Soglie | F38: =F25 -> 0.13632945 | G38: =H25 -> 0.41133483 | H38: =J25 -> 0.73084056 | O38: Spostamento Soglie | P38: =P25 -> 0.1402699 | Q38: =R25 -> 0.47681378 | R38: =T25 -> 1.5210662
E39: Riduzione su top 6 | F39: =G20 -> 0.10967955 | G39: =I20 -> 0.2094483 | H39: =K20 -> 0.32441361 | O39: Riduzione su top 6 | P39: =Q20 -> 0.043937892 | Q39: =S20 -> 0.18070697 | R39: =U20 -> 0.3617443
E40: Eliminazione Alert Falsi Positivi | F40: =G22 -> 0.13019001 | G40: =I22 -> 0.23786066 | H40: =K22 -> 0.37508797 | O40: Eliminazione Alert Falsi Positivi | P40: =Q22 -> 0.045742435 | Q40: =S22 -> 0.19915552 | R40: =U22 -> 0.39408867
E41: Eliminazione Alert Aperti | F41: =G24 -> 0.091531756 | G41: =I24 -> 0.18430884 | H41: =K24 -> 0.27957659 | O41: Eliminazione Alert Aperti | P41: =Q24 -> 0.04234122 | Q41: =S24 -> 0.16438356 | R41: =U24 -> 0.33312578

Sheet Analisi
A2: Le celle sono automatizzate a partire dall’analisi contenuta nel file Excel di accompagnamento
A4: Path
A6: flg_SCEN_IN_USO | B6: 1
A7: flag_anom_causale | B7: (All)
A9: DESCRIZIONE | B9: CODICE | C9: % POSIZIONE | D9: # POSIZIONE | E9: Nel perimetro | F9: Stato avanzamento | G9: Post Calibrazione | H9: Riduzione | J9: Value | K9: Percentage
A10: Operazione per conto di importo elevato per la causale ed il soggetto | B10: 14 | C10: 1084 | D10: 0.35035553 | E10: yes | F10: Done | G10: =[1]Simulazione!$G$45 -> 807 | H10: =C10-G10 -> 277 | I10: Totale Netech | J10: =COUNTA(DATA!B2:B1048576) -> 3178
A11: Versamento giornaliero di importo contante elevato per la causale ed il soggetto | B11: 100 | C11: 682 | D11: 0.22042663 | E11: yes | F11: Done | G11: =[2]Simulazione!$G$24 -> 386 | H11: =C11-G11 -> 296 | J11: =-(J10-J12) -> -84
A12: Versamento giornaliero di importo elevato per la causale ed il soggetto | B12: 95 | C12: 500 | D12: 0.1616031 | E12: yes | F12: Done | G12: =[3]Simulazione!$G$24 -> 344 | H12: =C12-G12 -> 156 | I12: Scenari in Uso | J12: =C19 -> 3094
A13: Clienti che registrano elevata movimentazione in ingresso con bonifici e assegni e successiva movimentazione verso l'estero | B13: DF03-02 | C13: 324 | D13: 0.10471881 | E13: yes | F13: Done | G13: =[4]Simulazione!$G$19 -> 189 | H13: =C13-G13 -> 135 | J13: =-(J12-J14) -> -67
A14: Operazioni con paese controparte ad altissimo rischio | B14: 90 | C14: 304 | D14: 0.098254686 | E14: yes | F14: Done | G14: =[5]Simulazione!$G$18 -> 139 | H14: =C14-G14 -> 165 | I14: Top 6 | J14: =SUMIF(E10:E18,"yes",C10:C18) -> 3027
A15: Bonifico con Paese dell'intermediario della controparte a rischio | B15: 30 | C15: 133 | D15: 0.042986425 | E15: yes | F15: Done | G15: =[6]Simulazione!$G$18 -> 67 | H15: =C15-G15 -> 66 | I15: On Going | J15: =-(J14-J16) -> 0 | K15: =ABS(J15/$J$14) -> 0
A16: Ricezione di bonifico e quasi contestuale uscita | B16: PM-SA31 | C16: 52 | D16: 0.016806723 | E16: no | G16: =C16 -> 52 | H16: =C16-G16 -> 0 | I16: Calibrata | J16: =SUMIF(F10:F18,"Done",C10:C18) -> 3027 | K16: =J16/$J$14 -> 1
A17: Triangolazione della controparte | B17: 83 | C17: 8 | D17: 0.0025856496 | E17: no | G17: =C17 -> 8 | H17: =C17-G17 -> 0 | I17: O/W still Alert | J17: =-(J16-J18) -> -1932
A18: Titolare o presentatore residente in paese a rischio | B18: 40 | C18: 7 | D18: 0.0022624434 | E18: no | G18: =C18 -> 7 | H18: =C18-G18 -> 0 | I18: O/W Alert Removed | J18: =SUM(H10:H18) -> 1095 | K18: =J18/J16 -> 0.3617443
A19: Grand Total | C19: 3094 | D19: 1
A21: Scenari gia clibrati | D21: Scenari non calibrati
A24: flg_SCEN_IN_USO | B24: 1 | D24: flg_SCEN_IN_USO | E24: 1
A25: CODICE | B25: (Multiple Items) | D25: CODICE | E25: (Multiple Items)
A27: flag_stato | B27: Count of POSIZIONE | D27: flag_stato | E27: Count of POSIZIONE
A28: 0 | B28: 1421 | D28: 0 | E28: 9
A29: 1 | B29: 1551 | D29: 1 | E29: 6
A30: (blank) | B30: 55 | D30: (blank) | E30: 52
A31: Grand Total | B31: 3027 | D31: Grand Total | E31: 67
A35: Riduzione volumen Alert
A36: Totale Netech In Uso | B36: =J12 -> 3094 | C36: =$J$18/B36 -> 0.3539108
A37: Totale top 6 | B37: =SUMIF(E10:E15,"yes",C10:C15) -> 3027 | C37: =$J$18/B37 -> 0.3617443
A38: Totale Perimetro Calibrazione Fatto | B38: =SUMIF(F10:F18,"Done",C10:C18) -> 3027 | C38: =$J$18/B38 -> 0.3617443
A40: Calcolo del False Positive Rate e Delta Open Alert
B41: Sum | C41: scen 14 | D41: scen 90 | E41: scen 30 | F41: scen 100 | G41: scen 95 | H41: scen DF03-02
A42: FP Scen Calibrata | B42: =SUM(C42:H42) -> 861 | C42: =[1]Simulazione!$I$45 -> 370 | D42: =[5]Simulazione!$I$18 -> 69 | E42: =[6]Simulazione!$I$18 -> 32 | F42: =[2]Simulazione!$I$24 -> 197 | G42: =[3]Simulazione!$I$24 -> 101 | H42: =[4]Simulazione!$I$19 -> 92
A43: Open Alert Scen Calibrata | B43: =SUM(C43:H43) -> 1071 | C43: =[1]Simulazione!$K$45 -> 437 | D43: =[5]Simulazione!$K$18 -> 70 | E43: =[6]Simulazione!$K$18 -> 35 | F43: =[2]Simulazione!$K$24 -> 189 | G43: =[3]Simulazione!$K$24 -> 243 | H43: =[4]Simulazione!$K$19 -> 97
A44: FP Scetari NON Calibrate | B44: =E28 -> 9
A45: Open Alert Scetari NON Calibrate | B45: =E29+E30 -> 58 | D45: Controllo
D46: =SUM(B42:B45)+J18 -> 3094
D47: =D46=B36 -> TRUE
A50: FP Totale Calibrata | B50: =B28 -> 1421 | D50: Controllo
A51: Open Alert Totale Calibrata | B51: =B29+B30 -> 1606 | D51: =SUM(B50:B51) -> 3027
A52: FP eliminata | B52: =B28-B42 -> 560 | D52: =D51=B38 -> TRUE
A53: Open eliminata | B53: =B30+B29-B43 -> 535
A55: FP Post calib / FP T0 | B55: =B52/B50 -> 0.39408867
...

Sheet DATA
A1: POSIZIONE | B1: CODICE | C1: DESCRIZIONE | D1: RILEVATA | E1: INTERMEDIARIO | F1: DIPENDENZA | G1: IN CARICO A | H1: SISTEMA AR | I1: STATO | J1: INDICE PREDITTIVO | K1: REGISTRAZIONE | L1: NUMERO RAPPORTO | M1: DATA OPERAZIONE | N1: CAUSALE ANALITICA | O1: CAUSALE SINTETICA | P1: PAESE INTERMED. CONTROP. | Q1: SEGNO | R1: IMPORTO | S1: DI CUI CONTANTE | T1: TITOLARE NDG | U1: CODICE FISCALE | V1: COGNOME E NOME / RAGIONE SOCIALE | W1: D21 SAE | X1: D22 ATECO | Y1: PAESE RESIDENZA | Z1: GESTORE | AA1: STATO VALUTAZIONE | AB1: ID ECCEZIONE | AC1: DATA ULT. VALUTAZIONE | AD1: UFFICIO | AE1: AUTORE | AF1: ULTIMA VALUTAZIONE | AG1: PRESENZA ALLEGATI | AH1: ALTRE VALUTAZIONI | AI1: ANNOMESE | AJ1: Stato | AK1: flag_stato | AL1: flg_SCEN_IN_USO | AM1: CDG | AN1: flag_OggValut | AO1: flag_anom_causale | AP1: ATECO_CODE | AQ1: SAE_CODE | AR1: SAE_ATECO_CODE | AS1: Classe_old | AT1: RES_ATECO | AU1: Classe
A2: 341994 | B2: DF03-02 | C2: Clienti che registrano elevata movimentazione in ingresso con bonifici e assegni e successiva movimentazione verso l'estero | D2: 45787 | E2: 53850 | F2: 122 | G2: 053850_122 | H2: Discovery Frodi | I2: Mai valutato | L2: 1223300002128 | M2: 20250409 | N2: 48 - Bonifico in arrivo | Q2: A - Avere | R2: 39500 | T2: 3711207 | U2: 8825020723 | V2: EXPRIVIA S.P.A. | W2: 430 - Imprese produttive | X2: 620 - PRODUZIONE DI SOFTWARE, CONSULENZA INFORMATICA E ATTIVITÀ CONNESSE | Y2: 086 - ITALIA | Z2: 1696 | AH2: 0 | AI2: 202504 | AJ2: ARCHIVIATA DA RPR | AK2: 0 | AL2: 1 | AO2: 0 | AP2: 620 | AQ2: 430 | AR2: 430620 | AS2: Classe di rischio 3 | AU2: Classe di rischio 3
A3: 341991 | B3: DF03-02 | C3: Clienti che registrano elevata movimentazione in ingresso con bonifici e assegni e successiva movimentazione verso l'estero | D3: 45787 | E3: 53850 | F3: 154 | G3: 053850_154 | H3: Discovery Frodi | I3: Mai valutato | L3: 1543300004860 | M3: 20250408 | N3: 48 - Bonifico in arrivo | Q3: A - Avere | R3: 30000 | T3: 3715569 | U3: 5424970654 | V3: SQUISITEZZE SRL | W3: 430 - Imprese produttive | X3: 472 - COMMERCIO AL DETTAGLIO DI PRODOTTI ALIMENTARI, BEVANDE E TABACCO IN ESERCIZI SPECIALIZZATI | Y3: 086 - ITALIA | Z3: 741 | AH3: 0 | AI3: 202504 | AJ3: ARCHIVIATA | AK3: 0 | AL3: 1 | AM3: 3715569 | AN3: 1 | AO3: 0 | AP3: 999 | AQ3: 430 | AR3: 430999 | AT3: 1 | AU3: Classe di rischio 1
A4: 341990 | B4: DF03-02 | C4: Clienti che registrano elevata movimentazione in ingresso con bonifici e assegni e successiva movimentazione verso l'estero | D4: 45787 | E4: 53850 | F4: 154 | G4: 053850_154 | H4: Discovery Frodi | I4: Mai valutato | L4: 1543300004860 | M4: 20250409 | N4: 48 - Bonifico in arrivo | Q4: A - Avere | R4: 33250 | T4: 3715569 | U4: 5424970654 | V4: SQUISITEZZE SRL | W4: 430 - Imprese produttive | X4: 472 - COMMERCIO AL DETTAGLIO DI PRODOTTI ALIMENTARI, BEVANDE E TABACCO IN ESERCIZI SPECIALIZZATI | Y4: 086 - ITALIA | Z4: 741 | AH4: 0 | AI4: 202504 | AJ4: ARCHIVIATA | AK4: 0 | AL4: 1 | AM4: 3715569 | AN4: 1 | AO4: 0 | AP4: 999 | AQ4: 430 | AR4: 430999 | AT4: 1 | AU4: Classe di rischio 1
A5: 341985 | B5: DF03-02 | C5: Clienti che registrano elevata movimentazione in ingresso con bonifici e assegni e successiva movimentazione verso l'estero | D5: 45787 | E5: 53850 | F5: 169 | G5: 053850_169 | H5: Discovery Frodi | I5: Mai valutato | L5: 1693302222377 | M5: 20250402 | N5: 48 - Bonifico in arrivo | Q5: A - Avere | R5: 147538.19 | T5: 4036414 | U5: 296820723 | V5: FRATELLI D'ADDATO S.R.L. | W5: 430 - Imprese produttive | X5: 467 - COMMERCIO ALL'INGROSSO SPECIALIZZATO DI ALTRI PRODOTTI | Y5: 086 - ITALIA | Z5: 1920 | AH5: 0 | AI5: 202504 | AJ5: ARCHIVIATA | AK5: 0 | AL5: 1 | AM5: 4036414 | AN5: 1 | AO5: 0 | AP5: 999 | AQ5: 430 | AR5: 430999 | AT5: 1 | AU5: Classe di rischio 1
A6: 341984 | B6: DF03-02 | C6: Clienti che registrano elevata movimentazione in ingresso con bonifici e assegni e successiva movimentazione verso l'estero | D6: 45787 | E6: 53850 | F6: 105 | G6: 053850_105 | H6: Discovery Frodi | I6: Mai valutato | L6: 1053306287103 | M6: 20250423 | N6: 48 - Bonifico in arrivo | Q6: A - Avere | R6: 1572927.6 | T6: 4263360 | U6: 5982300724 | V6: CAPURSO AZIENDA CASEARIA S.R.L. | W6: 430 - Imprese produttive | X6: 105 - INDUSTRIA LATTIERO-CASEARIA | Y6: 086 - ITALIA | Z6: 1058 | AH6: 0 | AI6: 202504 | AJ6: ARCHIVIATA | AK6: 0 | AL6: 1 | AO6: 0 | AP6: 999 | AQ6: 430 | AR6: 430999 | AT6: 1 | AU6: Classe di rischio 1
A7: 341982 | B7: DF03-02 | C7: Clienti che registrano elevata movimentazione in ingresso con bonifici e assegni e successiva movimentazione verso l'estero | D7: 45787 | E7: 53850 | F7: 153 | G7: 053850_153 | H7: Discovery Frodi | I7: Mai valutato | L7: 1533300663959 | M7: 20250422 | N7: 48 - Bonifico in arrivo | Q7: A - Avere | R7: 26730 | T7: 3721097 | U7: 10391641213 | V7: COMBES S.R.L. | W7: 430 - Imprese produttive | X7: 462 - COMMERCIO ALL'INGROSSO DI MATERIE PRIME AGRICOLE E DI ANIMALI VIVI | Y7: 086 - ITALIA | Z7: 1237 | AH7: 0 | AI7: 202504 | AJ7: ARCHIVIATA | AK7: 0 | AL7: 1 | AO7: 0 | AP7: 462 | AQ7: 430 | AR7: 430462 | AS7: Classe di rischio 3 | AU7: Classe di rischio 3
A8: 341980 | B8: DF03-02 | C8: Clienti che registrano elevata movimentazione in ingresso con bonifici e assegni e successiva movimentazione verso l'estero | D8: 45787 | E8: 53850 | F8: 192 | G8: 053850_192 | H8: Discovery Frodi | I8: Mai valutato | L8: 1923300183163 | M8: 20250422 | N8: 48 - Bonifico in arrivo | Q8: A - Avere | R8: 28000 | T8: 4695944 | U8: VLNFNC74H03H096P | V8: VALENTE FRANCESCO | W8: 615 - Altre famiglie produttrici | X8: 691 - ATTIVITÀ DEGLI STUDI LEGALI | Y8: 086 - ITALIA | Z8: 481 | AH8: 0 | AI8: 202504 | AJ8: ARCHIVIATA | AK8: 0 | AL8: 1 | AM8: 4695944 | AN8: 1 | AO8: 0 | AP8: 999 | AQ8: 615 | AR8: 615999 | AT8: 1 | AU8: Classe di rischio 3
A9: 341976 | B9: DF03-02 | C9: Clienti che registrano elevata movimentazione in ingresso con bonifici e assegni e successiva movimentazione verso l'estero | D9: 45787 | E9: 53850 | F9: 153 | G9: 053850_153 | H9: Discovery Frodi | I9: Mai valutato | L9: 1533300663959 | M9: 20250414 | N9: 48 - Bonifico in arrivo | Q9: A - Avere | R9: 30891.3 | T9: 3721097 | U9: 10391641213 | V9: COMBES S.R.L. | W9: 430 - Imprese produttive | X9: 462 - COMMERCIO ALL'INGROSSO DI MATERIE PRIME AGRICOLE E DI ANIMALI VIVI | Y9: 086 - ITALIA | Z9: 1237 | AH9: 0 | AI9: 202504 | AJ9: ARCHIVIATA | AK9: 0 | AL9: 1 | AO9: 0 | AP9: 462 | AQ9: 430 | AR9: 430462 | AS9: Classe di rischio 3 | AU9: Classe di rischio 3
A10: 341974 | B10: DF03-02 | C10: Clienti che registrano elevata movimentazione in ingresso con bonifici e assegni e successiva movimentazione verso l'estero | D10: 45787 | E10: 53850 | F10: 264 | G10: 053850_264 | H10: Discovery Frodi | I10: Mai valutato | L10: 2643300001866 | M10: 20250415 | N10: 48 - Bonifico in arrivo | Q10: A - Avere | R10: 100000 | T10: 1700310 | U10: VLLNNL74S19A801N | V10: AVALLONE ANTONIO ALFREDO | W10: 615 - Altre famiglie produttrici | X10: 711 - ATTIVITÀ DEGLI STUDI DI ARCHITETTURA, INGEGNERIA ED ALTRI STUDI TECNICI | Y10: 086 - ITALIA | Z10: 1851 | AH10: 0 | AI10: 202504 | AJ10: ARCHIVIATA | AK10: 0 | AL10: 1 | AO10: 0 | AP10: 999 | AQ10: 615 | AR10: 615999 | AT10: 1 | AU10: Classe di rischio 3
A11: 341971 | B11: DF03-02 | C11: Clienti che registrano elevata movimentazione in ingresso con bonifici e assegni e successiva movimentazione verso l'estero | D11: 45787 | E11: 53850 | F11: 125 | G11: 053850_125 | H11: Discovery Frodi | I11: Mai valutato | L11: 1253309512895 | M11: 20250407 | N11: 48 - Bonifico in arrivo | Q11: A - Avere | R11: 55652.61 | T11: 4795279 | U11: 1020090658 | V11: GIAGUARO - S.P.A. | W11: 430 - Imprese produttive | X11: 103 - LAVORAZIONE E CONSERVAZIONE DI FRUTTA E ORTAGGI | Y11: 086 - ITALIA | Z11: 982 | AH11: 0 | AI11: 202504 | AJ11: ARCHIVIATA DA RPR | AK11: 0 | AL11: 1 | AO11: 0 | AP11: 999 | AQ11: 430 | AR11: 430999 | AT11: 1 | AU11: Classe di rischio 1
A12: 341961 | B12: DF03-02 | C12: Clienti che registrano elevata movimentazione in ingresso con bonifici e assegni e successiva movimentazione verso l'estero | D12: 45787 | E12: 53850 | F12: 153 | G12: 053850_153 | H12: Discovery Frodi | I12: Mai valutato | L12: 1533300663959 | M12: 20250422 | N12: 48 - Bonifico in arrivo | Q12: A - Avere | R12: 28600.02 | T12: 3721097 | U12: 10391641213 | V12: COMBES S.R.L. | W12: 430 - Imprese produttive | X12: 462 - COMMERCIO ALL'INGROSSO DI MATERIE PRIME AGRICOLE E DI ANIMALI VIVI | Y12: 086 - ITALIA | Z12: 1237 | AH12: 0 | AI12: 202504 | AJ12: ARCHIVIATA | AK12: 0 | AL12: 1 | AO12: 0 | AP12: 462 | AQ12: 430 | AR12: 430462 | AS12: Classe di rischio 3 | AU12: Classe di rischio 3
A13: 341957 | B13: DF03-02 | C13: Clienti che registrano elevata movimentazione in ingresso con bonifici e assegni e successiva movimentazione verso l'estero | D13: 45787 | E13: 53850 | F13: 154 | G13: 053850_154 | H13: Discovery Frodi | I13: Mai valutato | L13: 1543300004860 | M13: 20250402 | N13: 48 - Bonifico in arrivo | Q13: A - Avere | R13: 55660 | T13: 3715569 | U13: 5424970654 | V13: SQUISITEZZE SRL | W13: 430 - Imprese produttive | X13: 472 - COMMERCIO AL DETTAGLIO DI PRODOTTI ALIMENTARI, BEVANDE E TABACCO IN ESERCIZI SPECIALIZZATI | Y13: 086 - ITALIA | Z13: 741 | AH13: 0 | AI13: 202504 | AJ13: ARCHIVIATA | AK13: 0 | AL13: 1 | AM13: 3715569 | AN13: 1 | AO13: 0 | AP13: 999 | AQ13: 430 | AR13: 430999 | AT13: 1 | AU13: Classe di rischio 1
A14: 341946 | B14: DF03-02 | C14: Clienti che registrano elevata movimentazione in ingresso con bonifici e assegni e successiva movimentazione verso l'estero | D14: 45787 | E14: 53850 | F14: 153 | G14: 053850_153 | H14: Discovery Frodi | I14: Mai valutato | L14: 1533300663959 | M14: 20250414 | N14: 48 - Bonifico in arrivo | Q14: A - Avere | R14: 25045.55 | T14: 3721097 | U14: 10391641213 | V14: COMBES S.R.L. | W14: 430 - Imprese produttive | X14: 462 - COMMERCIO ALL'INGROSSO DI MATERIE PRIME AGRICOLE E DI ANIMALI VIVI | Y14: 086 - ITALIA | Z14: 1237 | AH14: 0 | AI14: 202504 | AJ14: ARCHIVIATA | AK14: 0 | AL14: 1 | AO14: 0 | AP14: 462 | AQ14: 430 | AR14: 430462 | AS14: Classe di rischio 3 | AU14: Classe di rischio 3
A15: 341945 | B15: DF03-02 | C15: Clienti che registrano elevata movimentazione in ingresso con bonifici e assegni e successiva movimentazione verso l'estero | D15: 45787 | E15: 53850 | F15: 148 | G15: 053850_148 | H15: Discovery Frodi | I15: Mai valutato | L15: 1483300004308 | M15: 20250401 | N15: 48 - Bonifico in arrivo | Q15: A - Avere | R15: 41685 | T15: 4898674 | U15: 2936580642 | V15: GLOBAL TRADING S.R.L.S. | W15: 430 - Imprese produttive | X15: 467 - COMMERCIO ALL'INGROSSO SPECIALIZZATO DI ALTRI PRODOTTI | Y15: 086 - ITALIA | Z15: 1063 | AH15: 0 | AI15: 202504 | AJ15: ARCHIVIATA | AK15: 0 | AL15: 1 | AO15: 0 | AP15: 999 | AQ15: 430 | AR15: 430999 | AT15: 1 | AU15: Classe di rischio 1
A16: 341944 | B16: DF03-02 | C16: Clienti che registrano elevata movimentazione in ingresso con bonifici e assegni e successiva movimentazione verso l'estero | D16: 45787 | E16: 53850 | F16: 103 | G16: 053850_103 | H16: Discovery Frodi | I16: Mai valutato | L16: 1033306967935 | M16: 20250403 | N16: G1 - Versamento assegni tratti su altro intermediario | Q16: A - Avere | R16: 25126.83 | T16: 155052 | U16: 2563580725 | V16: ITALSUD CARBURANTI SRL | W16: 430 - Imprese produttive | X16: 467 - COMMERCIO ALL'INGROSSO SPECIALIZZATO DI ALTRI PRODOTTI | Y16: 086 - ITALIA | Z16: 1926 | AH16: 0 | AI16: 202504 | AJ16: ARCHIVIATA | AK16: 0 | AL16: 1 | AM16: 155052 | AN16: 1 | AO16: 0 | AP16: 999 | AQ16: 430 | AR16: 430999 | AT16: 1 | AU16: Classe di rischio 1
A17: 341941 | B17: DF03-02 | C17: Clienti che registrano elevata movimentazione in ingresso con bonifici e assegni e successiva movimentazione verso l'estero | D17: 45787 | E17: 53850 | F17: 125 | G17: 053850_125 | H17: Discovery Frodi | I17: Mai valutato | L17: 1253309512895 | M17: 20250402 | N17: 48 - Bonifico in arrivo | Q17: A - Avere | R17: 178429.19 | T17: 4795279 | U17: 1020090658 | V17: GIAGUARO - S.P.A. | W17: 430 - Imprese produttive | X17: 103 - LAVORAZIONE E CONSERVAZIONE DI FRUTTA E ORTAGGI | Y17: 086 - ITALIA | Z17: 982 | AH17: 0 | AI17: 202504 | AJ17: ARCHIVIATA DA RPR | AK17: 0 | AL17: 1 | AO17: 0 | AP17: 999 | AQ17: 430 | AR17: 430999 | AT17: 1 | AU17: Classe di rischio 1
A18: 341937 | B18: DF03-02 | C18: Clienti che registrano elevata movimentazione in ingresso con bonifici e assegni e successiva movimentazione verso l'estero | D18: 45787 | E18: 53850 | F18: 122 | G18: 053850_122 | H18: Discovery Frodi | I18: Mai valutato | L18: 1223300001682 | M18: 20250429 | N18: 48 - Bonifico in arrivo | Q18: A - Avere | R18: 350419.46 | T18: 3711207 | U18: 8825020723 | V18: EXPRIVIA S.P.A. | W18: 430 - Imprese produttive | X18: 620 - PRODUZIONE DI SOFTWARE, CONSULENZA INFORMATICA E ATTIVITÀ CONNESSE | Y18: 086 - ITALIA | Z18: 1696 | AH18: 0 | AI18: 202504 | AJ18: ARCHIVIATA DA RPR | AK18: 0 | AL18: 1 | AO18: 0 | AP18: 620 | AQ18: 430 | AR18: 430620 | AS18: Classe di rischio 3 | AU18: Classe di rischio 3
A19: 341931 | B19: DF03-02 | C19: Clienti che registrano elevata movimentazione in ingresso con bonifici e assegni e successiva movimentazione verso l'estero | D19: 45787 | E19: 53850 | F19: 105 | G19: 053850_105 | H19: Discovery Frodi | I19: Mai valutato | L19: 1053306287103 | M19: 20250424 | N19: 48 - Bonifico in arrivo | Q19: A - Avere | R19: 208134.89 | T19: 4263360 | U19: 5982300724 | V19: CAPURSO AZIENDA CASEARIA S.R.L. | W19: 430 - Imprese produttive | X19: 105 - INDUSTRIA LATTIERO-CASEARIA | Y19: 086 - ITALIA | Z19: 1058 | AH19: 0 | AI19: 202504 | AJ19: ARCHIVIATA | AK19: 0 | AL19: 1 | AO19: 0 | AP19: 999 | AQ19: 430 | AR19: 430999 | AT19: 1 | AU19: Classe di rischio 1
A20: 341927 | B20: DF03-02 | C20: Clienti che registrano elevata movimentazione in ingresso con bonifici e assegni e successiva movimentazione verso l'estero | D20: 45787 | E20: 53850 | F20: 268 | G20: 053850_268 | H20: Discovery Frodi | I20: Mai valutato | L20: 2683300010038 | M20: 20250402 | N20: 48 - Bonifico in arrivo | Q20: A - Avere | R20: 120007.68 | T20: 1604219 | U20: 952850790 | V20: SABOLIO SRL | W20: 430 - Imprese produttive | X20: 104 - PRODUZIONE DI OLI E GRASSI VEGETALI E ANIMALI | Y20: 086 - ITALIA | Z20: 1627 | AH20: 0 | AI20: 202504 | AJ20: IN VALUTAZIONE RPR | AK20: 1 | AL20: 1 | AO20: 0 | AP20: 999 | AQ20: 430 | AR20: 430999 | AT20: 1 | AU20: Classe di rischio 1
A21: 341924 | B21: DF03-02 | C21: Clienti che registrano elevata movimentazione in ingresso con bonifici e assegni e successiva movimentazione verso l'estero | D21: 45787 | E21: 53850 | F21: 122 | G21: 053850_122 | H21: Discovery Frodi | I21: Mai valutato | L21: 1223300001682 | M21: 20250429 | N21: 48 - Bonifico in arrivo | Q21: A - Avere | R21: 87840 | T21: 3711207 | U21: 8825020723 | V21: EXPRIVIA S.P.A. | W21: 430 - Imprese produttive | X21: 620 - PRODUZIONE DI SOFTWARE, CONSULENZA INFORMATICA E ATTIVITÀ CONNESSE | Y21: 086 - ITALIA | Z21: 1696 | AH21: 0 | AI21: 202504 | AJ21: ARCHIVIATA DA RPR | AK21: 0 | AL21: 1 | AO21: 0 | AP21: 620 | AQ21: 430 | AR21: 430620 | AS21: Classe di rischio 3 | AU21: Classe di rischio 3
A22: 341919 | B22: DF03-02 | C22: Clienti che registrano elevata movimentazione in ingresso con bonifici e assegni e successiva movimentazione verso l'estero | D22: 45787 | E22: 53850 | F22: 153 | G22: 053850_153 | H22: Discovery Frodi | I22: Mai valutato | L22: 1533300663959 | M22: 20250428 | N22: 48 - Bonifico in arrivo | Q22: A - Avere | R22: 28809 | T22: 3721097 | U22: 10391641213 | V22: COMBES S.R.L. | W22: 430 - Imprese produttive | X22: 462 - COMMERCIO ALL'INGROSSO DI MATERIE PRIME AGRICOLE E DI ANIMALI VIVI | Y22: 086 - ITALIA | Z22: 1237 | AH22: 0 | AI22: 202504 | AJ22: ARCHIVIATA | AK22: 0 | AL22: 1 | AO22: 0 | AP22: 462 | AQ22: 430 | AR22: 430462 | AS22: Classe di rischio 3 | AU22: Classe di rischio 3
A23: 341912 | B23: DF03-02 | C23: Clienti che registrano elevata movimentazione in ingresso con bonifici e assegni e successiva movimentazione verso l'estero | D23: 45787 | E23: 53850 | F23: 122 | G23: 053850_122 | H23: Discovery Frodi | I23: Mai valutato | L23: 1223300001682 | M23: 20250429 | N23: 48 - Bonifico in arrivo | Q23: A - Avere | R23: 99430 | T23: 3711207 | U23: 8825020723 | V23: EXPRIVIA S.P.A. | W23: 430 - Imprese produttive | X23: 620 - PRODUZIONE DI SOFTWARE, CONSULENZA INFORMATICA E ATTIVITÀ CONNESSE | Y23: 086 - ITALIA | Z23: 1696 | AH23: 0 | AI23: 202504 | AJ23: ARCHIVIATA DA RPR | AK23: 0 | AL23: 1 | AO23: 0 | AP23: 620 | AQ23: 430 | AR23: 430620 | AS23: Classe di rischio 3 | AU23: Classe di rischio 3
A24: 341910 | B24: DF03-02 | C24: Clienti che registrano elevata movimentazione in ingresso con bonifici e assegni e successiva movimentazione verso l'estero | D24: 45787 | E24: 53850 | F24: 148 | G24: 053850_148 | H24: Discovery Frodi | I24: Mai valutato | L24: 1483300006067 | M24: 20250414 | N24: 48 - Bonifico in arrivo | Q24: A - Avere | R24: 40000 | T24: 3737044 | U24: 15554071009 | V24: PVM SRL | W24: 430 - Imprese produttive | X24: 522 - ATTIVITÀ DI SUPPORTO AI TRASPORTI | Y24: 086 - ITALIA | Z24: 1196 | AH24: 0 | AI24: 202504 | AJ24: ARCHIVIATA | AK24: 0 | AL24: 1 | AO24: 0 | AP24: 999 | AQ24: 430 | AR24: 430999 | AT24: 1 | AU24: Classe di rischio 1
A25: 341904 | B25: DF03-02 | C25: Clienti che registrano elevata movimentazione in ingresso con bonifici e assegni e successiva movimentazione verso l'estero | D25: 45787 | E25: 53850 | F25: 122 | G25: 053850_122 | H25: Discovery Frodi | I25: Mai valutato | L25: 1223300002128 | M25: 20250409 | N25: 48 - Bonifico in arrivo | Q25: A - Avere | R25: 77996.14 | T25: 3711207 | U25: 8825020723 | V25: EXPRIVIA S.P.A. | W25: 430 - Imprese produttive | X25: 620 - PRODUZIONE DI SOFTWARE, CONSULENZA INFORMATICA E ATTIVITÀ CONNESSE | Y25: 086 - ITALIA | Z25: 1696 | AH25: 0 | AI25: 202504 | AJ25: ARCHIVIATA DA RPR | AK25: 0 | AL25: 1 | AO25: 0 | AP25: 620 | AQ25: 430 | AR25: 430620 | AS25: Classe di rischio 3 | AU25: Classe di rischio 3
A26: 341896 | B26: DF03-02 | C26: Clienti che registrano elevata movimentazione in ingresso con bonifici e assegni e successiva movimentazione verso l'estero | D26: 45787 | E26: 53850 | F26: 109 | G26: 053850_109 | H26: Discovery Frodi | I26: Mai valutato | L26: 1093306672844 | M26: 20250416 | N26: 48 - Bonifico in arrivo | Q26: A - Avere | R26: 800000 | T26: 440311 | U26: 3550290724 | V26: ZENTRUM BARI S.R.L. | W26: 430 - Imprese produttive | X26: 451 - COMMERCIO DI AUTOVEICOLI | Y26: 086 - ITALIA | Z26: 1903 | AH26: 0 | AI26: 202504 | AJ26: ARCHIVIATA | AK26: 0 | AL26: 1 | AM26: 440311 | AN26: 1 | AO26: 0 | AP26: 451 | AQ26: 430 | AR26: 430451 | AS26: Classe di rischio 3 | AU26: Classe di rischio 3
A27: 341890 | B27: DF03-02 | C27: Clienti che registrano elevata movimentazione in ingresso con bonifici e assegni e successiva movimentazione verso l'estero | D27: 45787 | E27: 53850 | F27: 122 | G27: 053850_122 | H27: Discovery Frodi | I27: Mai valutato | L27: 1223300002128 | M27: 20250428 | N27: 48 - Bonifico in arrivo | Q27: A - Avere | R27: 32860 | T27: 3711207 | U27: 8825020723 | V27: EXPRIVIA S.P.A. | W27: 430 - Imprese produttive | X27: 620 - PRODUZIONE DI SOFTWARE, CONSULENZA INFORMATICA E ATTIVITÀ CONNESSE | Y27: 086 - ITALIA | Z27: 1696 | AH27: 0 | AI27: 202504 | AJ27: ARCHIVIATA DA RPR | AK27: 0 | AL27: 1 | AO27: 0 | AP27: 620 | AQ27: 430 | AR27: 430620 | AS27: Classe di rischio 3 | AU27: Classe di rischio 3
A28: 341888 | B28: DF03-02 | C28: Clienti che registrano elevata movimentazione in ingresso con bonifici e assegni e successiva movimentazione verso l'estero | D28: 45787 | E28: 53850 | F28: 122 | G28: 053850_122 | H28: Discovery Frodi | I28: Mai valutato | L28: 1223300002128 | M28: 20250409 | N28: 48 - Bonifico in arrivo | Q28: A - Avere | R28: 34002.77 | T28: 3711207 | U28: 8825020723 | V28: EXPRIVIA S.P.A. | W28: 430 - Imprese produttive | X28: 620 - PRODUZIONE DI SOFTWARE, CONSULENZA INFORMATICA E ATTIVITÀ CONNESSE | Y28: 086 - ITALIA | Z28: 1696 | AH28: 0 | AI28: 202504 | AJ28: ARCHIVIATA DA RPR | AK28: 0 | AL28: 1 | AO28: 0 | AP28: 620 | AQ28: 430 | AR28: 430620 | AS28: Classe di rischio 3 | AU28: Classe di rischio 3
A29: 341886 | B29: DF03-02 | C29: Clienti che registrano elevata movimentazione in ingresso con bonifici e assegni e successiva movimentazione verso l'estero | D29: 45787 | E29: 53850 | F29: 132 | G29: 053850_132 | H29: Discovery Frodi | I29: Mai valutato | L29: 1323300003714 | M29: 20250417 | N29: 48 - Bonifico in arrivo | Q29: A - Avere | R29: 32313.6 | T29: 3724103 | U29: 2178850760 | V29: DESMA SOCIETA' A RESPONSABILITA' LIMITATA SEMPLIFICATA | W29: 430 - Imprese produttive | X29: 522 - ATTIVITÀ DI SUPPORTO AI TRASPORTI | Y29: 086 - ITALIA | Z29: 823 | AH29: 0 | AI29: 202504 | AJ29: ARCHIVIATA DA RPR | AK29: 0 | AL29: 1 | AO29: 0 | AP29: 999 | AQ29: 430 | AR29: 430999 | AT29: 1 | AU29: Classe di rischio 1
A30: 341866 | B30: DF03-02 | C30: Clienti che registrano elevata movimentazione in ingresso con bonifici e assegni e successiva movimentazione verso l'estero | D30: 45787 | E30: 53850 | F30: 128 | G30: 053850_128 | H30: Discovery Frodi | I30: Mai valutato | L30: 1283300001665 | M30: 20250402 | N30: G1 - Versamento assegni tratti su altro intermediario | Q30: A - Avere | R30: 53722.17 | T30: 4254896 | U30: 6234730726 | V30: SPECIALMANGIMI GALTIERI S.P.A | W30: 430 - Imprese produttive | X30: 109 - PRODUZIONE DI PRODOTTI PER L'ALIMENTAZIONE DEGLI ANIMALI | Y30: 086 - ITALIA | Z30: 1919 | AH30: 0 | AI30: 202504 | AJ30: ARCHIVIATA | AK30: 0 | AL30: 1 | AO30: 0 | AP30: 999 | AQ30: 430 | AR30: 430999 | AT30: 1 | AU30: Classe di rischio 1
A31: 341864 | B31: DF03-02 | C31: Clienti che registrano elevata movimentazione in ingresso con bonifici e assegni e successiva movimentazione verso l'estero | D31: 45787 | E31: 53850 | F31: 109 | G31: 053850_109 | H31: Discovery Frodi | I31: Mai valutato | L31: 1093306674353 | M31: 20250404 | N31: G2 - Versamento assegni tratti sullo stesso intermediario | Q31: A - Avere | R31: 130000 | T31: 4916449 | U31: 8176830720 | V31: CENTRO AUTOVEICOLI S.R.L. | W31: 430 - Imprese produttive | X31: 451 - COMMERCIO DI AUTOVEICOLI | Y31: 086 - ITALIA | Z31: 1903 | AH31: 0 | AI31: 202504 | AJ31: ARCHIVIATA | AK31: 0 | AL31: 1 | AO31: 0 | AP31: 451 | AQ31: 430 | AR31: 430451 | AS31: Classe di rischio 3 | AU31: Classe di rischio 3
A32: 341861 | B32: DF03-02 | C32: Clienti che registrano elevata movimentazione in ingresso con bonifici e assegni e successiva movimentazione verso l'estero | D32: 45787 | E32: 53850 | F32: 175 | G32: 053850_175 | H32: Discovery Frodi | I32: Mai valutato | L32: 1753302203127 | M32: 20250407 | N32: G1 - Versamento assegni tratti su altro intermediario | Q32: A - Avere | R32: 29089.99 | T32: 4160138 | U32: 484200779 | V32: DE.RA.DO. SRL | W32: 430 - Imprese produttive | X32: 031 - PESCA | Y32: 086 - ITALIA | Z32: 739 | AH32: 0 | AI32: 202504 | AJ32: IN VALUTAZIONE RPR | AK32: 1 | AL32: 1 | AM32: 4160138 | AN32: 1 | AO32: 0 | AP32: 999 | AQ32: 430 | AR32: 430999 | AT32: 1 | AU32: Classe di rischio 1
A33: 341857 | B33: DF03-02 | C33: Clienti che registrano elevata movimentazione in ingresso con bonifici e assegni e successiva movimentazione verso l'estero | D33: 45787 | E33: 53850 | F33: 122 | G33: 053850_122 | H33: Discovery Frodi | I33: Mai valutato | L33: 1223300002128 | M33: 20250409 | N33: 48 - Bonifico in arrivo | Q33: A - Avere | R33: 32524.58 | T33: 3711207 | U33: 8825020723 | V33: EXPRIVIA S.P.A. | W33: 430 - Imprese produttive | X33: 620 - PRODUZIONE DI SOFTWARE, CONSULENZA INFORMATICA E ATTIVITÀ CONNESSE | Y33: 086 - ITALIA | Z33: 1696 | AH33: 0 | AI33: 202504 | AJ33: ARCHIVIATA DA RPR | AK33: 0 | AL33: 1 | AO33: 0 | AP33: 620 | AQ33: 430 | AR33: 430620 | AS33: Classe di rischio 3 | AU33: Classe di rischio 3
A34: 341856 | B34: DF03-02 | C34: Clienti che registrano elevata movimentazione in ingresso con bonifici e assegni e successiva movimentazione verso l'estero | D34: 45787 | E34: 53850 | F34: 122 | G34: 053850_122 | H34: Discovery Frodi | I34: Mai valutato | L34: 1223300002128 | M34: 20250409 | N34: 48 - Bonifico in arrivo | Q34: A - Avere | R34: 125998.16 | T34: 3711207 | U34: 8825020723 | V34: EXPRIVIA S.P.A. | W34: 430 - Imprese produttive | X34: 620 - PRODUZIONE DI SOFTWARE, CONSULENZA INFORMATICA E ATTIVITÀ CONNESSE | Y34: 086 - ITALIA | Z34: 1696 | AH34: 0 | AI34: 202504 | AJ34: ARCHIVIATA DA RPR | AK34: 0 | AL34: 1 | AO34: 0 | AP34: 620 | AQ34: 430 | AR34: 430620 | AS34: Classe di rischio 3 | AU34: Classe di rischio 3
A35: 341851 | B35: DF03-02 | C35: Clienti che registrano elevata movimentazione in ingresso con bonifici e assegni e successiva movimentazione verso l'estero | D35: 45787 | E35: 53850 | F35: 191 | G35: 053850_191 | H35: Discovery Frodi | I35: Mai valutato | L35: 1913300068122 | M35: 20250429 | N35: 48 - Bonifico in arrivo | Q35: A - Avere | R35: 30000 | T35: 4918280 | U35: 3480410798 | V35: OLEARIA CHIERA S.R.L. | W35: 430 - Imprese produttive | X35: 104 - PRODUZIONE DI OLI E GRASSI VEGETALI E ANIMALI | Y35: 086 - ITALIA | AH35: 0 | AI35: 202504 | AJ35: ARCHIVIATA | AK35: 0 | AL35: 1 | AO35: 0 | AP35: 999 | AQ35: 430 | AR35: 430999 | AT35: 1 | AU35: Classe di rischio 1
A36: 341846 | B36: DF03-02 | C36: Clienti che registrano elevata movimentazione in ingresso con bonifici e assegni e successiva movimentazione verso l'estero | D36: 45787 | E36: 53850 | F36: 122 | G36: 053850_122 | H36: Discovery Frodi | I36: Mai valutato | L36: 1223300001682 | M36: 20250409 | N36: 48 - Bonifico in arrivo | Q36: A - Avere | R36: 119376.46 | T36: 3711207 | U36: 8825020723 | V36: EXPRIVIA S.P.A. | W36: 430 - Imprese produttive | X36: 620 - PRODUZIONE DI SOFTWARE, CONSULENZA INFORMATICA E ATTIVITÀ CONNESSE | Y36: 086 - ITALIA | Z36: 1696 | AH36: 0 | AI36: 202504 | AJ36: ARCHIVIATA DA RPR | AK36: 0 | AL36: 1 | AO36: 0 | AP36: 620 | AQ36: 430 | AR36: 430620 | AS36: Classe di rischio 3 | AU36: Classe di rischio 3
A37: 341837 | B37: DF03-02 | C37: Clienti che registrano elevata movimentazione in ingresso con bonifici e assegni e successiva movimentazione verso l'estero | D37: 45787 | E37: 53850 | F37: 132 | G37: 053850_132 | H37: Discovery Frodi | I37: Mai valutato | L37: 1323300003714 | M37: 20250407 | N37: 48 - Bonifico in arrivo | Q37: A - Avere | R37: 28274 | T37: 3724103 | U37: 2178850760 | V37: DESMA SOCIETA' A RESPONSABILITA' LIMITATA SEMPLIFICATA | W37: 430 - Imprese produttive | X37: 522 - ATTIVITÀ DI SUPPORTO AI TRASPORTI | Y37: 086 - ITALIA | Z37: 823 | AH37: 0 | AI37: 202504 | AJ37: ARCHIVIATA DA RPR | AK37: 0 | AL37: 1 | AO37: 0 | AP37: 999 | AQ37: 430 | AR37: 430999 | AT37: 1 | AU37: Classe di rischio 1
A38: 341832 | B38: DF03-02 | C38: Clienti che registrano elevata movimentazione in ingresso con bonifici e assegni e successiva movimentazione verso l'estero | D38: 45787 | E38: 53850 | F38: 122 | G38: 053850_122 | H38: Discovery Frodi | I38: Mai valutato | L38: 1223300002128 | M38: 20250410 | N38: 48 - Bonifico in arrivo | Q38: A - Avere | R38: 39297.59 | T38: 3711207 | U38: 8825020723 | V38: EXPRIVIA S.P.A. | W38: 430 - Imprese produttive | X38: 620 - PRODUZIONE DI SOFTWARE, CONSULENZA INFORMATICA E ATTIVITÀ CONNESSE | Y38: 086 - ITALIA | Z38: 1696 | AH38: 0 | AI38: 202504 | AJ38: ARCHIVIATA DA RPR | AK38: 0 | AL38: 1 | AO38: 0 | AP38: 620 | AQ38: 430 | AR38: 430620 | AS38: Classe di rischio 3 | AU38: Classe di rischio 3
A39: 341819 | B39: DF03-02 | C39: Clienti che registrano elevata movimentazione in ingresso con bonifici e assegni e successiva movimentazione verso l'estero | D39: 45787 | E39: 53850 | F39: 153 | G39: 053850_153 | H39: Discovery Frodi | I39: Mai valutato | L39: 1533300663957 | M39: 20250414 | N39: 48 - Bonifico in arrivo | Q39: A - Avere | R39: 48960.38 | T39: 3720623 | U39: 3067020648 | V39: E F ALLEVA S.R.L. | W39: 430 - Imprese produttive | X39: 462 - COMMERCIO ALL'INGROSSO DI MATERIE PRIME AGRICOLE E DI ANIMALI VIVI | Y39: 086 - ITALIA | Z39: 1055 | AH39: 0 | AI39: 202504 | AJ39: ARCHIVIATA | AK39: 0 | AL39: 1 | AO39: 0 | AP39: 462 | AQ39: 430 | AR39: 430462 | AS39: Classe di rischio 3 | AU39: Classe di rischio 3
A40: 341814 | B40: DF03-02 | C40: Clienti che registrano elevata movimentazione in ingresso con bonifici e assegni e successiva movimentazione verso l'estero | D40: 45787 | E40: 53850 | F40: 122 | G40: 053850_122 | H40: Discovery Frodi | I40: Mai valutato | L40: 1223300001682 | M40: 20250428 | N40: 48 - Bonifico in arrivo | Q40: A - Avere | R40: 83000 | T40: 3711207 | U40: 8825020723 | V40: EXPRIVIA S.P.A. | W40: 430 - Imprese produttive | X40: 620 - PRODUZIONE DI SOFTWARE, CONSULENZA INFORMATICA E ATTIVITÀ CONNESSE | Y40: 086 - ITALIA | Z40: 1696 | AH40: 0 | AI40: 202504 | AJ40: ARCHIVIATA DA RPR | AK40: 0 | AL40: 1 | AO40: 0 | AP40: 620 | AQ40: 430 | AR40: 430620 | AS40: Classe di rischio 3 | AU40: Classe di rischio 3
...
